2025-09-21 20:47:07,626 - __main__ - INFO - Starting complete data mining pipeline
2025-09-21 20:47:07,627 - __main__ - INFO - Starting stage: knowledge_graph
2025-09-21 20:47:07,627 - __main__ - INFO - Building medical knowledge graph...
2025-09-21 20:47:07,627 - __main__ - ERROR - Failed stage: knowledge_graph - no such column: p.publication_year
2025-09-21 20:47:07,629 - __main__ - ERROR - Pipeline failed: no such column: p.publication_year
2025-09-21 20:47:07,631 - __main__ - ERROR - Traceback (most recent call last):
  File "C:\Users\samis\Desktop\MyBiome\back_end\data_mining\data_mining_orchestrator.py", line 286, in run_complete_pipeline
    self._build_knowledge_graph()
  File "C:\Users\samis\Desktop\MyBiome\back_end\data_mining\data_mining_orchestrator.py", line 371, in _build_knowledge_graph
    cursor = conn.execute(query, params)
sqlite3.OperationalError: no such column: p.publication_year

2025-09-21 20:47:07,631 - __main__ - ERROR - Pipeline failed: no such column: p.publication_year
2025-09-21 20:47:07,631 - __main__ - ERROR - Traceback (most recent call last):
  File "C:\Users\samis\Desktop\MyBiome\back_end\data_mining\data_mining_orchestrator.py", line 926, in main
    orchestrator.run_complete_pipeline()
  File "C:\Users\samis\Desktop\MyBiome\back_end\data_mining\data_mining_orchestrator.py", line 286, in run_complete_pipeline
    self._build_knowledge_graph()
  File "C:\Users\samis\Desktop\MyBiome\back_end\data_mining\data_mining_orchestrator.py", line 371, in _build_knowledge_graph
    cursor = conn.execute(query, params)
sqlite3.OperationalError: no such column: p.publication_year

2025-09-22 19:18:54,691 - __main__ - INFO - Starting complete data mining pipeline
2025-09-22 19:18:54,691 - __main__ - INFO - Starting stage: knowledge_graph
2025-09-22 19:18:54,691 - __main__ - INFO - Building medical knowledge graph...
2025-09-22 19:18:54,691 - __main__ - ERROR - Failed stage: knowledge_graph - no such column: p.publication_year
2025-09-22 19:18:54,691 - __main__ - ERROR - Pipeline failed: no such column: p.publication_year
2025-09-22 19:18:54,691 - __main__ - ERROR - Traceback (most recent call last):
  File "C:\Users\samis\Desktop\MyBiome\back_end\data_mining\data_mining_orchestrator.py", line 286, in run_complete_pipeline
    self._build_knowledge_graph()
  File "C:\Users\samis\Desktop\MyBiome\back_end\data_mining\data_mining_orchestrator.py", line 371, in _build_knowledge_graph
    cursor = conn.execute(query, params)
sqlite3.OperationalError: no such column: p.publication_year

2025-09-22 19:18:54,691 - __main__ - ERROR - Pipeline failed: no such column: p.publication_year
2025-09-22 19:18:54,691 - __main__ - ERROR - Traceback (most recent call last):
  File "C:\Users\samis\Desktop\MyBiome\back_end\data_mining\data_mining_orchestrator.py", line 926, in main
    orchestrator.run_complete_pipeline()
  File "C:\Users\samis\Desktop\MyBiome\back_end\data_mining\data_mining_orchestrator.py", line 286, in run_complete_pipeline
    self._build_knowledge_graph()
  File "C:\Users\samis\Desktop\MyBiome\back_end\data_mining\data_mining_orchestrator.py", line 371, in _build_knowledge_graph
    cursor = conn.execute(query, params)
sqlite3.OperationalError: no such column: p.publication_year

2025-09-22 19:19:46,028 - __main__ - INFO - Starting complete data mining pipeline
2025-09-22 19:19:46,028 - __main__ - INFO - Starting stage: knowledge_graph
2025-09-22 19:19:46,028 - __main__ - INFO - Building medical knowledge graph...
2025-09-22 19:19:46,028 - __main__ - ERROR - Failed stage: knowledge_graph - no such column: i.condition
2025-09-22 19:19:46,028 - __main__ - ERROR - Pipeline failed: no such column: i.condition
2025-09-22 19:19:46,028 - __main__ - ERROR - Traceback (most recent call last):
  File "C:\Users\samis\Desktop\MyBiome\back_end\data_mining\data_mining_orchestrator.py", line 286, in run_complete_pipeline
    self._build_knowledge_graph()
  File "C:\Users\samis\Desktop\MyBiome\back_end\data_mining\data_mining_orchestrator.py", line 371, in _build_knowledge_graph
    cursor = conn.execute(query, params)
sqlite3.OperationalError: no such column: i.condition

2025-09-22 19:19:46,028 - __main__ - ERROR - Pipeline failed: no such column: i.condition
2025-09-22 19:19:46,028 - __main__ - ERROR - Traceback (most recent call last):
  File "C:\Users\samis\Desktop\MyBiome\back_end\data_mining\data_mining_orchestrator.py", line 926, in main
    orchestrator.run_complete_pipeline()
  File "C:\Users\samis\Desktop\MyBiome\back_end\data_mining\data_mining_orchestrator.py", line 286, in run_complete_pipeline
    self._build_knowledge_graph()
  File "C:\Users\samis\Desktop\MyBiome\back_end\data_mining\data_mining_orchestrator.py", line 371, in _build_knowledge_graph
    cursor = conn.execute(query, params)
sqlite3.OperationalError: no such column: i.condition

2025-09-22 19:20:09,163 - __main__ - INFO - Starting complete data mining pipeline
2025-09-22 19:20:09,163 - __main__ - INFO - Starting stage: knowledge_graph
2025-09-22 19:20:09,163 - __main__ - INFO - Building medical knowledge graph...
2025-09-22 19:20:09,164 - __main__ - ERROR - Failed stage: knowledge_graph - no such column: i.evidence_type
2025-09-22 19:20:09,164 - __main__ - ERROR - Pipeline failed: no such column: i.evidence_type
2025-09-22 19:20:09,164 - __main__ - ERROR - Traceback (most recent call last):
  File "C:\Users\samis\Desktop\MyBiome\back_end\data_mining\data_mining_orchestrator.py", line 286, in run_complete_pipeline
    self._build_knowledge_graph()
  File "C:\Users\samis\Desktop\MyBiome\back_end\data_mining\data_mining_orchestrator.py", line 371, in _build_knowledge_graph
    cursor = conn.execute(query, params)
sqlite3.OperationalError: no such column: i.evidence_type

2025-09-22 19:20:09,165 - __main__ - ERROR - Pipeline failed: no such column: i.evidence_type
2025-09-22 19:20:09,165 - __main__ - ERROR - Traceback (most recent call last):
  File "C:\Users\samis\Desktop\MyBiome\back_end\data_mining\data_mining_orchestrator.py", line 926, in main
    orchestrator.run_complete_pipeline()
  File "C:\Users\samis\Desktop\MyBiome\back_end\data_mining\data_mining_orchestrator.py", line 286, in run_complete_pipeline
    self._build_knowledge_graph()
  File "C:\Users\samis\Desktop\MyBiome\back_end\data_mining\data_mining_orchestrator.py", line 371, in _build_knowledge_graph
    cursor = conn.execute(query, params)
sqlite3.OperationalError: no such column: i.evidence_type

